<?xml version="1.0" ?>
<!-- =================================================================================== -->
<!-- |    This document was autogenerated by xacro from /home/markvdm/RobotSetup/catkin_ws/src/kuka_iiwa_med_interface/med_description/urdf/med.urdf.xacro | -->
<!-- |    EDITING THIS FILE BY HAND IS NOT RECOMMENDED                                 | -->
<!-- =================================================================================== -->
<robot name="med" xmlns:controller="http://playerstage.sourceforge.net/gazebo/xmlschema/#controller" xmlns:interface="http://playerstage.sourceforge.net/gazebo/xmlschema/#interface" xmlns:sensor="http://playerstage.sourceforge.net/gazebo/xmlschema/#sensor">
  <!--    <xacro:arg name="bubbles" default="True"/>-->
  <material name="Black">
    <color rgba="0.0 0.0 0.0 1.0"/>
  </material>
  <material name="Blue">
    <color rgba="0.0 0.0 0.8 1.0"/>
  </material>
  <material name="Green">
    <color rgba="0.0 0.8 0.0 1.0"/>
  </material>
  <material name="Grey">
    <color rgba="0.4 0.4 0.4 1.0"/>
  </material>
  <material name="Orange">
    <color rgba="1.0 0.4235294117647059 0.0392156862745098 1.0"/>
  </material>
  <material name="Brown">
    <color rgba="0.8705882352941177 0.8117647058823529 0.7647058823529411 1.0"/>
  </material>
  <material name="Red">
    <color rgba="0.8 0.0 0.0 1.0"/>
  </material>
  <material name="White">
    <color rgba="1.0 1.0 1.0 1.0"/>
  </material>
  <material name="LightGrey">
    <color rgba="0.7 0.7 0.7 1"/>
  </material>
  <material name="DarkGray">
    <color rgba="0.2 0.2 0.2 1"/>
  </material>
  <material name="DarkDarkGray">
    <color rgba="0.1 0.1 0.1 1"/>
  </material>
  <!-- Make a base link. -->
  <link name="med_base" type="fixed">
    <inertial>
      <mass value="0"/>
      <inertia ixx="0" ixy="0" ixz="0" iyy="0" iyz="0" izz="0"/>
    </inertial>
  </link>
  <!--joint between {parent} and link_0-->
  <joint name="med_base_med_kuka_joint" type="fixed">
    <origin rpy="0 0 0" xyz="0 0 0"/>
    <parent link="med_base"/>
    <child link="med_kuka_link_0"/>
  </joint>
  <link name="med_kuka_link_0">
    <inertial>
      <origin rpy="0 0 0" xyz="-0.1 0 0.07"/>
      <mass value="5"/>
      <inertia ixx="0.05" ixy="0" ixz="0" iyy="0.06" iyz="0" izz="0.03"/>
    </inertial>
    <visual>
      <origin rpy="0 0 0" xyz="0 0 0"/>
      <geometry>
        <mesh filename="package://med_description/meshes/iiwa14_med/visual/link_0.stl"/>
      </geometry>
      <material name="Grey"/>
    </visual>
    <collision>
      <origin rpy="0 0 0" xyz="0 0 0"/>
      <geometry>
        <mesh filename="package://med_description/meshes/iiwa14_med/visual/link_0.stl"/>
      </geometry>
      <material name="Grey"/>
    </collision>
    <self_collision_checking>
      <origin rpy="0 0 0" xyz="0 0 0"/>
      <geometry>
        <capsule length="0.25" radius="0.15"/>
      </geometry>
    </self_collision_checking>
  </link>
  <!-- joint between link_0 and link_1 -->
  <joint name="med_kuka_joint_1" type="revolute">
    <parent link="med_kuka_link_0"/>
    <child link="med_kuka_link_1"/>
    <origin rpy="0 0 0" xyz="0 0 0.1575"/>
    <axis xyz="0 0 1"/>
    <limit effort="300" lower="-2.9670597283903604" upper="2.9670597283903604" velocity="1.48352986419518"/>
    <safety_controller k_position="100" k_velocity="2" soft_lower_limit="-2.9321531433504737" soft_upper_limit="2.9321531433504737"/>
    <dynamics damping="0.5"/>
  </joint>
  <link name="med_kuka_link_1">
    <inertial>
      <origin rpy="0 0 0" xyz="0 -0.03 0.12"/>
      <mass value="4"/>
      <inertia ixx="0.1" ixy="0" ixz="0" iyy="0.09" iyz="0" izz="0.02"/>
    </inertial>
    <visual>
      <origin rpy="0 0 0" xyz="0 0 -0.1575"/>
      <geometry>
        <mesh filename="package://med_description/meshes/iiwa14_med/visual/link_1.stl"/>
      </geometry>
      <material name="White"/>
    </visual>
    <collision>
      <origin rpy="0 0 0" xyz="0 0 -0.1575"/>
      <geometry>
        <mesh filename="package://med_description/meshes/iiwa14_med/visual/link_1.stl"/>
      </geometry>
      <material name="White"/>
    </collision>
  </link>
  <!-- joint between link_1 and link_2 -->
  <joint name="med_kuka_joint_2" type="revolute">
    <parent link="med_kuka_link_1"/>
    <child link="med_kuka_link_2"/>
    <origin rpy="1.5707963267948966   0 3.141592653589793" xyz="0 0 0.2025"/>
    <axis xyz="0 0 1"/>
    <limit effort="300" lower="-2.0943951023931953" upper="2.0943951023931953" velocity="1.48352986419518"/>
    <safety_controller k_position="100" k_velocity="2" soft_lower_limit="-2.0594885173533086" soft_upper_limit="2.0594885173533086"/>
    <dynamics damping="0.5"/>
  </joint>
  <link name="med_kuka_link_2">
    <inertial>
      <origin rpy="0 0 0" xyz="0.0003 0.059 0.042"/>
      <mass value="4"/>
      <inertia ixx="0.05" ixy="0" ixz="0" iyy="0.018" iyz="0" izz="0.044"/>
    </inertial>
    <visual>
      <origin rpy="0 0 3.1415" xyz="0 0 0"/>
      <geometry>
        <mesh filename="package://med_description/meshes/iiwa14_med/visual/A2_origin_updated.stl"/>
      </geometry>
      <material name="White"/>
    </visual>
    <collision>
      <origin rpy="0 0 3.1415" xyz="0 0 0"/>
      <geometry>
        <mesh filename="package://med_description/meshes/iiwa14_med/visual/link_2.stl"/>
      </geometry>
      <material name="White"/>
    </collision>
  </link>
  <!-- joint between link_2 and link_3 -->
  <joint name="med_kuka_joint_3" type="revolute">
    <parent link="med_kuka_link_2"/>
    <child link="med_kuka_link_3"/>
    <origin rpy="1.5707963267948966 0 3.141592653589793" xyz="0 0.2380 0"/>
    <axis xyz="0 0 1"/>
    <limit effort="300" lower="-2.9670597283903604" upper="2.9670597283903604" velocity="1.7453292519943295"/>
    <safety_controller k_position="100" k_velocity="2" soft_lower_limit="-2.9321531433504737" soft_upper_limit="2.9321531433504737"/>
    <dynamics damping="0.5"/>
  </joint>
  <link name="med_kuka_link_3">
    <inertial>
      <origin rpy="0 0 0" xyz="0 0.03 0.13"/>
      <mass value="3"/>
      <inertia ixx="0.08" ixy="0" ixz="0" iyy="0.075" iyz="0" izz="0.01"/>
    </inertial>
    <visual>
      <origin rpy="0 0 0" xyz="0 0 0"/>
      <geometry>
        <mesh filename="package://med_description/meshes/iiwa14_med/visual/A3_origin_updated.stl"/>
      </geometry>
      <material name="White"/>
    </visual>
    <collision>
      <origin rpy="0 0 0" xyz="0 0 0"/>
      <geometry>
        <mesh filename="package://med_description/meshes/iiwa14_med/visual/link_3.stl"/>
      </geometry>
      <material name="White"/>
    </collision>
  </link>
  <!-- joint between link_3 and link_4 -->
  <joint name="med_kuka_joint_4" type="revolute">
    <parent link="med_kuka_link_3"/>
    <child link="med_kuka_link_4"/>
    <origin rpy="1.5707963267948966 0 0" xyz="0 0 0.1820"/>
    <axis xyz="0 0 1"/>
    <limit effort="300" lower="-2.0943951023931953" upper="2.0943951023931953" velocity="1.3089969389957472"/>
    <safety_controller k_position="100" k_velocity="2" soft_lower_limit="-2.0594885173533086" soft_upper_limit="2.0594885173533086"/>
    <dynamics damping="0.5"/>
  </joint>
  <link name="med_kuka_link_4">
    <inertial>
      <origin rpy="0 0 0" xyz="0 0.067 0.034"/>
      <mass value="2.7"/>
      <inertia ixx="0.03" ixy="0" ixz="0" iyy="0.01" iyz="0" izz="0.029"/>
    </inertial>
    <visual>
      <origin rpy="0 0 0" xyz="0 0 0"/>
      <geometry>
        <mesh filename="package://med_description/meshes/iiwa14_med/visual/A4_origin_updated.stl"/>
      </geometry>
      <material name="White"/>
    </visual>
    <collision>
      <origin rpy="0 0 0" xyz="0 0 0"/>
      <geometry>
        <mesh filename="package://med_description/meshes/iiwa14_med/visual/link_4.stl"/>
      </geometry>
      <material name="White"/>
    </collision>
  </link>
  <!-- joint between link_4 and link_5 -->
  <joint name="med_kuka_joint_5" type="revolute">
    <parent link="med_kuka_link_4"/>
    <child link="med_kuka_link_5"/>
    <origin rpy="-1.5707963267948966 3.141592653589793 0" xyz="0 0.2170 0"/>
    <axis xyz="0 0 1"/>
    <limit effort="300" lower="-2.9670597283903604" upper="2.9670597283903604" velocity="2.2689280275926285"/>
    <safety_controller k_position="100" k_velocity="2" soft_lower_limit="-2.9321531433504737" soft_upper_limit="2.9321531433504737"/>
    <dynamics damping="0.5"/>
  </joint>
  <link name="med_kuka_link_5">
    <inertial>
      <origin rpy="0 0 0" xyz="0.0001 0.021 0.076"/>
      <mass value="1.7"/>
      <inertia ixx="0.02" ixy="0" ixz="0" iyy="0.018" iyz="0" izz="0.005"/>
    </inertial>
    <visual>
      <origin rpy="0 0 3.1415" xyz="0 0 0"/>
      <geometry>
        <mesh filename="package://med_description/meshes/iiwa14_med/visual/A5_origin_updated.stl"/>
      </geometry>
      <material name="White"/>
    </visual>
    <collision>
      <origin rpy="0 0 3.1415" xyz="0 0 0"/>
      <geometry>
        <mesh filename="package://med_description/meshes/iiwa14_med/visual/link_5.stl"/>
      </geometry>
      <material name="White"/>
    </collision>
  </link>
  <!-- joint between link_5 and link_6 -->
  <joint name="med_kuka_joint_6" type="revolute">
    <parent link="med_kuka_link_5"/>
    <child link="med_kuka_link_6"/>
    <origin rpy="1.5707963267948966 0 0" xyz="0 0 0.1825"/>
    <!-- <origin xyz="0 -0.0607 0.1825" rpy="${PI / 2} 0 0"/> -->
    <axis xyz="0 0 1"/>
    <limit effort="300" lower="-2.0943951023931953" upper="2.0943951023931953" velocity="2.356194490192345"/>
    <safety_controller k_position="100" k_velocity="2" soft_lower_limit="-2.0594885173533086" soft_upper_limit="2.0594885173533086"/>
    <dynamics damping="0.5"/>
  </joint>
  <link name="med_kuka_link_6">
    <inertial>
      <origin rpy="0 0 0" xyz="0 0.0006 0.0004"/>
      <mass value="1.8"/>
      <inertia ixx="0.005" ixy="0" ixz="0" iyy="0.0036" iyz="0" izz="0.0047"/>
    </inertial>
    <visual>
      <origin rpy="3.1415 3.1415 0" xyz="0 0 -0.0607"/>
      <geometry>
        <mesh filename="package://med_description/meshes/iiwa14_med/visual/A6_origin_updated.stl"/>
      </geometry>
      <material name="White"/>
    </visual>
    <collision>
      <origin rpy="3.1415 3.1415 0" xyz="0 0 -0.0607"/>
      <geometry>
        <mesh filename="package://med_description/meshes/iiwa14_med/visual/link_6.stl"/>
      </geometry>
      <material name="White"/>
    </collision>
  </link>
  <!-- joint between link_6 and link_7 -->
  <joint name="med_kuka_joint_7" type="revolute">
    <parent link="med_kuka_link_6"/>
    <child link="med_kuka_link_7"/>
    <origin rpy="-1.5707963267948966 3.141592653589793 0" xyz="0 0.0910 0"/>
    <!-- <origin xyz="0 0.0910 -0.0607" rpy="${- PI / 2} ${PI} 0"/>       -->
    <axis xyz="0 0 1"/>
    <limit effort="300" lower="-3.0543261909900763" upper="3.0543261909900763" velocity="2.356194490192345"/>
    <safety_controller k_position="100" k_velocity="2" soft_lower_limit="-3.01941960595019" soft_upper_limit="3.01941960595019"/>
    <dynamics damping="0.5"/>
  </joint>
  <link name="med_kuka_link_7">
    <inertial>
      <origin rpy="0 0 0" xyz="0 0 0.02"/>
      <mass value="0.3"/>
      <inertia ixx="0.001" ixy="0" ixz="0" iyy="0.001" iyz="0" izz="0.001"/>
    </inertial>
    <visual>
      <origin rpy="0 0 0" xyz="0 0 0"/>
      <geometry>
        <mesh filename="package://med_description/meshes/iiwa14_med/visual/A7_origin_updated.stl"/>
      </geometry>
      <material name="Grey"/>
    </visual>
    <collision>
      <origin rpy="0 0 0" xyz="0 0 0"/>
      <geometry>
        <mesh filename="package://med_description/meshes/iiwa14_med/visual/link_7.stl"/>
      </geometry>
      <material name="Grey"/>
    </collision>
  </link>
  <joint name="med_kuka_joint_ee" type="fixed">
    <parent link="med_kuka_link_7"/>
    <child link="med_kuka_link_ee"/>
    <origin rpy="0 0 0" xyz="0 0 0.035"/>
  </joint>
  <link name="med_kuka_link_ee">
    <inertial>
      <mass value="0"/>
      <inertia ixx="0" ixy="0" ixz="0" iyy="0" iyz="0" izz="0"/>
    </inertial>
  </link>
  <!-- Link0 -->
  <gazebo reference="med_kuka_link_0">
    <kinematic>0</kinematic>
    <mu1>0.2</mu1>
    <mu2>0.2</mu2>
  </gazebo>
  <!-- Link1 -->
  <gazebo reference="med_kuka_link_1">
    <kinematic>0</kinematic>
    <mu1>0.2</mu1>
    <mu2>0.2</mu2>
  </gazebo>
  <!-- Link2 -->
  <gazebo reference="med_kuka_link_2">
    <kinematic>0</kinematic>
    <mu1>0.2</mu1>
    <mu2>0.2</mu2>
  </gazebo>
  <!-- Link3 -->
  <gazebo reference="med_kuka_link_3">
    <kinematic>0</kinematic>
    <mu1>0.2</mu1>
    <mu2>0.2</mu2>
  </gazebo>
  <!-- Link4 -->
  <gazebo reference="med_kuka_link_4">
    <kinematic>0</kinematic>
    <mu1>0.2</mu1>
    <mu2>0.2</mu2>
  </gazebo>
  <!-- Link5 -->
  <gazebo reference="med_kuka_link_5">
    <kinematic>0</kinematic>
    <mu1>0.2</mu1>
    <mu2>0.2</mu2>
  </gazebo>
  <!-- Link6 -->
  <gazebo reference="med_kuka_link_6">
    <kinematic>0</kinematic>
    <mu1>0.2</mu1>
    <mu2>0.2</mu2>
  </gazebo>
  <!-- Link7 -->
  <gazebo reference="med_kuka_link_7">
    <kinematic>0</kinematic>
    <mu1>0.2</mu1>
    <mu2>0.2</mu2>
  </gazebo>
  <transmission name="med_kuka_tran_1">
    <type>transmission_interface/SimpleTransmission</type>
    <joint name="med_kuka_joint_1">
      <hardwareInterface>hardware_interface/PositionJointInterface</hardwareInterface>
    </joint>
    <actuator name="med_kuka_motor_1">
      <mechanicalReduction>1</mechanicalReduction>
    </actuator>
  </transmission>
  <transmission name="med_kuka_tran_2">
    <type>transmission_interface/SimpleTransmission</type>
    <joint name="med_kuka_joint_2">
      <hardwareInterface>hardware_interface/PositionJointInterface</hardwareInterface>
    </joint>
    <actuator name="med_kuka_motor_2">
      <mechanicalReduction>1</mechanicalReduction>
    </actuator>
  </transmission>
  <transmission name="med_kuka_tran_3">
    <type>transmission_interface/SimpleTransmission</type>
    <joint name="med_kuka_joint_3">
      <hardwareInterface>hardware_interface/PositionJointInterface</hardwareInterface>
    </joint>
    <actuator name="med_kuka_motor_3">
      <mechanicalReduction>1</mechanicalReduction>
    </actuator>
  </transmission>
  <transmission name="med_kuka_tran_4">
    <type>transmission_interface/SimpleTransmission</type>
    <joint name="med_kuka_joint_4">
      <hardwareInterface>hardware_interface/PositionJointInterface</hardwareInterface>
    </joint>
    <actuator name="med_kuka_motor_4">
      <mechanicalReduction>1</mechanicalReduction>
    </actuator>
  </transmission>
  <transmission name="med_kuka_tran_5">
    <type>transmission_interface/SimpleTransmission</type>
    <joint name="med_kuka_joint_5">
      <hardwareInterface>hardware_interface/PositionJointInterface</hardwareInterface>
    </joint>
    <actuator name="med_kuka_motor_5">
      <mechanicalReduction>1</mechanicalReduction>
    </actuator>
  </transmission>
  <transmission name="med_kuka_tran_6">
    <type>transmission_interface/SimpleTransmission</type>
    <joint name="med_kuka_joint_6">
      <hardwareInterface>hardware_interface/PositionJointInterface</hardwareInterface>
    </joint>
    <actuator name="med_kuka_motor_6">
      <mechanicalReduction>1</mechanicalReduction>
    </actuator>
  </transmission>
  <transmission name="med_kuka_tran_7">
    <type>transmission_interface/SimpleTransmission</type>
    <joint name="med_kuka_joint_7">
      <hardwareInterface>hardware_interface/PositionJointInterface</hardwareInterface>
    </joint>
    <actuator name="med_kuka_motor_7">
      <mechanicalReduction>1</mechanicalReduction>
    </actuator>
  </transmission>
  <joint name="wsg50_plate_joint" type="fixed">
    <origin rpy="0 0 -1.5708" xyz="0 0 0"/>
    <!-- <origin xyz="0 0 0" rpy="0 0 -1.5708"/> -->
    <parent link="med_kuka_link_ee"/>
    <child link="wsg50_plate"/>
  </joint>
  <!-- GRIPPER PLATE -->
  <link name="wsg50_plate">
    <inertial>
      <mass value="0.0"/>
      <!-- This is not the true mass -->
      <origin xyz="0 0 0"/>
      <inertia ixx="1.0" ixy="0.0" ixz="0.0" iyy="1.0" iyz="0.0" izz="1.0"/>
      <!-- This are not the true inertia -->
    </inertial>
    <visual>
      <origin rpy="0 0 0" xyz="0.0 0 0"/>
      <geometry>
        <mesh filename="package://med_description/meshes/wsg50/wsg50_plate.stl" scale="1 1 1"/>
        <!--box size="0.146 0.05 0.0735"/-->
      </geometry>
      <material name="grey">
        <color rgba="0.5 0.5 0.5 1"/>
      </material>
    </visual>
    <collision>
      <origin rpy="0 0 0" xyz="0.0 0 0"/>
      <geometry>
        <!--box size="0.146 0.05 0.0735"/-->
        <mesh filename="package://med_description/meshes/wsg50/wsg50_plate.stl" scale="1 1 1"/>
      </geometry>
    </collision>
  </link>
  <gazebo reference="wsg50_plate">
    <material>Gazebo/Grey</material>
    <turnGravityOff>false</turnGravityOff>
  </gazebo>
  <!-- GRIPPER -->
  <joint name="wsg50_anterior_gripper_joint" type="fixed">
    <origin rpy="0 0 0" xyz="0 0 0.01"/>
    <!-- <origin xyz="0 0 0" rpy="0 0 -1.5708"/> -->
    <parent link="wsg50_plate"/>
    <child link="wsg50_base_link"/>
  </joint>
  <!-- BASE LINK -->
  <link name="wsg50_base_link">
    <inertial>
      <mass value="1.48"/>
      <origin xyz="0.00363 -0.00829 0.015"/>
      <!--inertia ixx="1.0" ixy="0.0" ixz="0.0"
                    iyy="100.0" iyz="0.0"
                    izz="1.0" /-->
      <inertia ixx="0.0" ixy="0.0" ixz="0.0" iyy="0.0" iyz="0.0" izz="0.0"/>
    </inertial>
    <visual>
      <origin rpy="0 0 0" xyz="0.0 0 0"/>
      <geometry>
        <mesh filename="package://med_description/meshes/wsg50/WSG50_110.stl" scale="1 1 1"/>
        <!--box size="0.146 0.05 0.0735"/-->
      </geometry>
      <material name="grey">
        <color rgba="0.5 0.5 0.5 1"/>
      </material>
    </visual>
    <collision>
      <origin rpy="0 0 0" xyz="0.0 0 0"/>
      <geometry>
        <!--box size="0.146 0.05 0.0735"/-->
        <mesh filename="package://med_description/meshes/wsg50/WSG50_110.stl" scale="1 1 1"/>
      </geometry>
    </collision>
  </link>
  <gazebo reference="wsg50_base_link">
    <material>Gazebo/Grey</material>
    <turnGravityOff>false</turnGravityOff>
  </gazebo>
  <joint name="wsg50_center_joint" type="fixed">
    <origin rpy="0 0 0" xyz="0 0 0.023"/>
    <!--origin xyz="-0.0067 0 0.049" rpy="0 0 0" /-->
    <parent link="wsg50_base_link"/>
    <child link="wsg50_center"/>
  </joint>
  <link name="wsg50_center">
    <inertial>
      <mass value="0"/>
      <inertia ixx="0" ixy="0" ixz="0" iyy="0" iyz="0" izz="0"/>
    </inertial>
  </link>
  <!-- GRIPPER LEFT -->
  <joint name="wsg50_finger_left_joint" type="prismatic">
    <limit effort="1.0" lower="-0.055" upper="-0.03" velocity="1.0"/>
    <origin rpy="0 0 0" xyz="0 0 0"/>
    <!--origin xyz="-0.0067 0 0.049" rpy="0 0 0" /-->
    <parent link="wsg50_base_link"/>
    <child link="wsg50_gripper_left"/>
    <dynamics damping="100" friction="100"/>
    <axis xyz="1 0 0"/>
  </joint>
  <transmission name="wsg50_base_trans_left">
    <type>transmission_interface/SimpleTransmission</type>
    <actuator name="wsg50_base_motor_left">
      <mechanicalReduction>1</mechanicalReduction>
    </actuator>
    <joint name="wsg50_finger_left_joint">
      <hardwareInterface>hardware_interface/PositionJointInterface</hardwareInterface>
    </joint>
  </transmission>
  <link name="wsg50_gripper_left">
    <inertial>
      <mass value="0.1"/>
      <origin xyz="0 0 0"/>
      <inertia ixx="1.0" ixy="0.0" ixz="0.0" iyy="1.0" iyz="0.0" izz="1.0"/>
    </inertial>
    <visual>
      <origin rpy="0 0 0" xyz="0.0 0 0"/>
      <geometry>
        <mesh filename="package://med_description/meshes/wsg50/GUIDE_WSG50_110.stl" scale="0.001 0.001 0.001"/>
        <!--box size="0.0175 0.03 0.024"/-->
      </geometry>
      <material name="black">
        <color rgba="0 0 0 1"/>
      </material>
    </visual>
    <collision>
      <origin rpy="0 0 0" xyz="0 0 0"/>
      <geometry>
        <!--box size="0.0175 0.03 0.024"/-->
        <mesh filename="package://med_description/meshes/wsg50/GUIDE_WSG50_110.stl" scale="0.001 0.001 0.001"/>
      </geometry>
    </collision>
    <contact_coefficients kd="1.0" kp="1000.0" mu="0"/>
  </link>
  <gazebo reference="wsg50_gripper_left">
    <material>Gazebo/Blue</material>
    <turnGravityOff>false</turnGravityOff>
  </gazebo>
  <!-- Bubbles -->
  <joint name="wsg50_guide_joint_finger_left" type="fixed">
    <origin rpy="0 0 0" xyz="-0.009 0 .089"/>
    <parent link="wsg50_gripper_left"/>
    <child link="wsg50_finger_left"/>
    <dynamics damping="100" friction="100"/>
    <axis xyz="1 0 0"/>
    <limit effort="100" velocity="100"/>
  </joint>
  <link name="wsg50_finger_left">
    <inertial>
      <mass value="0.1"/>
      <origin xyz="0 0 0"/>
      <inertia ixx="1.0" ixy="0.0" ixz="0.0" iyy="1.0" iyz="0.0" izz="1.0"/>
    </inertial>
    <visual>
      <origin rpy="3.1415 -.61 0" xyz="-0.05277 0 0.05375"/>
      <geometry>
        <mesh filename="package://med_description/meshes/bubbles/collision/bubble.stl" scale="0.001 0.001 0.001"/>
      </geometry>
      <material name="pastel">
        <color rgba="0.8588 0.5255 0.6588 1"/>
      </material>
    </visual>
    <collision>
      <origin rpy="3.1415 -.61 0" xyz="-0.05277 0 0.05375"/>
      <geometry>
        <mesh filename="package://med_description/meshes/bubbles/collision/bubble.stl" scale="0.001 0.001 0.001"/>
      </geometry>
    </collision>
    <contact_coefficients kd="1.0" kp="1000.0" mu="0"/>
  </link>
  <!-- LEFT CAMERA FRAME -->
  <joint name="wsg50_left_bubble_camera_frame_fake_joint" type="fixed">
    <origin rpy="3.1415 -.61 0" xyz="-0.05277 0 0.05375"/>
    <parent link="wsg50_finger_left"/>
    <child link="left_bubble_camera_frame"/>
  </joint>
  <link name="left_bubble_camera_frame">
    <inertial>
      <mass value="0.0"/>
      <origin xyz="0 0 0"/>
      <inertia ixx="0.0" ixy="0.0" ixz="0.0" iyy="0.0" iyz="0.0" izz="0.0"/>
    </inertial>
  </link>
  <gazebo reference="wsg50_finger_left">
    <material>Gazebo/Blue</material>
    <turnGravityOff>false</turnGravityOff>
  </gazebo>
  <!-- GRIPPER RIGHT -->
  <joint name="wsg50_finger_right_joint" type="prismatic">
    <limit effort="1.0" lower="0.03" upper="0.055" velocity="1.0"/>
    <origin rpy="0 0 3.14159" xyz="0 0 0"/>
    <parent link="wsg50_base_link"/>
    <child link="wsg50_gripper_right"/>
    <axis xyz="-1 0 0"/>
    <dynamics damping="100" friction="100"/>
  </joint>
  <transmission name="wsg50_base_trans_right">
    <type>transmission_interface/SimpleTransmission</type>
    <actuator name="wsg50_base_motor_right">
      <mechanicalReduction>1</mechanicalReduction>
    </actuator>
    <joint name="wsg50_finger_right_joint">
      <hardwareInterface>hardware_interface/PositionJointInterface</hardwareInterface>
    </joint>
  </transmission>
  <link name="wsg50_gripper_right">
    <inertial>
      <mass value="0.1"/>
      <origin xyz="0 0 0"/>
      <inertia ixx="1.0" ixy="0.0" ixz="0.0" iyy="1.0" iyz="0.0" izz="1.0"/>
    </inertial>
    <visual>
      <origin rpy="0 0 0" xyz="0.0 0 0"/>
      <geometry>
        <mesh filename="package://med_description/meshes/wsg50/GUIDE_WSG50_110.stl" scale="0.001 0.001 0.001"/>
        <!--box size="0.0175 0.03 0.024"/-->
      </geometry>
      <material name="black">
        <color rgba="0 0 0 1"/>
      </material>
    </visual>
    <collision>
      <origin rpy="0 0 0" xyz="0 0 0"/>
      <geometry>
        <!--box size="0.0175 0.03 0.024"/-->
        <mesh filename="package://med_description/meshes/wsg50/GUIDE_WSG50_110.stl" scale="0.001 0.001 0.001"/>
      </geometry>
    </collision>
    <contact_coefficients kd="1.0" kp="1000.0" mu="0"/>
  </link>
  <gazebo reference="gripper_right">
    <material>Gazebo/White</material>
    <turnGravityOff>false</turnGravityOff>
  </gazebo>
  <!-- Bubbles -->
  <joint name="wsg50_guide_joint_finger_right" type="fixed">
    <origin rpy="0 0 0" xyz="-0.009 0 .089"/>
    <parent link="wsg50_gripper_right"/>
    <child link="wsg50_finger_right"/>
    <dynamics damping="100" friction="100"/>
    <axis xyz="1 0 0"/>
    <limit effort="100" velocity="100"/>
  </joint>
  <link name="wsg50_finger_right">
    <inertial>
      <mass value="0.1"/>
      <origin xyz="0 0 0"/>
      <inertia ixx="1.0" ixy="0.0" ixz="0.0" iyy="1.0" iyz="0.0" izz="1.0"/>
    </inertial>
    <visual>
      <origin rpy="3.1415 -.61 0" xyz="-0.05277 0 0.05375"/>
      <geometry>
        <mesh filename="package://med_description/meshes/bubbles/collision/bubble.stl" scale="0.001 0.001 0.001"/>
      </geometry>
      <material name="pastel">
        <color rgba="0.8588 0.5255 0.6588 1"/>
      </material>
    </visual>
    <collision>
      <origin rpy="3.1415 -.61 0" xyz="-0.05277 0 0.05375"/>
      <geometry>
        <mesh filename="package://med_description/meshes/bubbles/visual/bubble.stl" scale="0.001 0.001 0.001"/>
      </geometry>
    </collision>
    <contact_coefficients kd="1.0" kp="1000.0" mu="0"/>
    <contact_coefficients kd="1.0" kp="1000.0" mu="0"/>
  </link>
  <!-- RIGHT CAMERA FRAME -->
  <joint name="wsg50_right_bubble_camera_frame_fake_joint" type="fixed">
    <origin rpy="3.1415 -.61 0" xyz="-0.05277 0 0.05375"/>
    <parent link="wsg50_finger_right"/>
    <child link="right_bubble_camera_frame"/>
  </joint>
  <link name="right_bubble_camera_frame">
    <inertial>
      <mass value="0.0"/>
      <origin xyz="0 0 0"/>
      <inertia ixx="0.0" ixy="0.0" ixz="0.0" iyy="0.0" iyz="0.0" izz="0.0"/>
    </inertial>
  </link>
  <gazebo reference="wsg50_finger_right">
    <material>Gazebo/White</material>
    <turnGravityOff>false</turnGravityOff>
  </gazebo>
  <!-- GRASP FRAME -->
  <joint name="wsg50_grasp_frame_fake_joint" type="fixed">
    <!-- BUBBLES -->
    <origin rpy="0 0 0" xyz="0 0 0.194"/>
    <!-- May be worth considering the parameter finger_tip-->
    <!-- <origin xyz="0 0 0" rpy="0 0 -1.5708"/> -->
    <parent link="wsg50_base_link"/>
    <child link="grasp_frame"/>
  </joint>
  <link name="grasp_frame">
    <inertial>
      <mass value="0.0"/>
      <origin xyz="0 0 0"/>
      <inertia ixx="0.0" ixy="0.0" ixz="0.0" iyy="0.0" iyz="0.0" izz="0.0"/>
    </inertial>
  </link>
  <!-- RIGHT FINGER TIP FRAME -->
  <joint name="wsg50_right_finger_tip_fake_joint" type="fixed">
    <origin rpy="0 0 3.14159" xyz="0 0 0.121"/>
    <!-- May be worth considering the parameter finger_tip-->
    <!-- <origin xyz="0 0 0" rpy="0 0 -1.5708"/> -->
    <parent link="wsg50_finger_right"/>
    <child link="wsg50_finger_right_tip"/>
  </joint>
  <link name="wsg50_finger_right_tip">
    <inertial>
      <mass value="0.0"/>
      <origin xyz="0 0 0"/>
      <inertia ixx="0.0" ixy="0.0" ixz="0.0" iyy="0.0" iyz="0.0" izz="0.0"/>
    </inertial>
  </link>
  <!-- LEFT FINGER TIP FRAME -->
  <joint name="wsg50_left_finger_tip_fake_joint" type="fixed">
    <origin rpy="0 0 0" xyz="0 0 0.121"/>
    <!-- May be worth considering the parameter finger_tip-->
    <!-- <origin xyz="0 0 0" rpy="0 0 -1.5708"/> -->
    <parent link="wsg50_finger_left"/>
    <child link="wsg50_finger_left_tip"/>
  </joint>
  <link name="wsg50_finger_left_tip">
    <inertial>
      <mass value="0.0"/>
      <origin xyz="0 0 0"/>
      <inertia ixx="0.0" ixy="0.0" ixz="0.0" iyy="0.0" iyz="0.0" izz="0.0"/>
    </inertial>
  </link>
  <gazebo>
    <plugin filename="libgazebo_ros_control.so" name="gazebo_ros_control">
      <robotNamespace>med</robotNamespace>
      <legacyModeNS>false</legacyModeNS>
    </plugin>
  </gazebo>
  <gazebo>
    <plugin filename="libgazebo_ros_moveit_planning_scene.so" name="gazebo_ros_moveit_planning_scene">
      <robotName>med</robotName>
      <robotNamespace>med</robotNamespace>
      <!--  This must be the same as the root frame of the robot you're using -->
      <frameId>med_base</frameId>
      <excludedModels>collision_sphere</excludedModels>
      <scalePrimitivesFactor>1.1</scalePrimitivesFactor>
    </plugin>
  </gazebo>
  <link name="world"/>
  <joint name="world_joint" type="fixed">
    <parent link="world"/>
    <child link="med_base"/>
    <origin rpy="0.0 0.0 0.0" xyz="0.0 0.0 0.0"/>
  </joint>
</robot>

